(cards-against-django)SensitiveDependence:cards-against-django phildini$ CAH_KEY=12345 python manage.py runserver --settings=cah.settings.local
Traceback (most recent call last):
  File "manage.py", line 17, in <module>
    execute_from_command_line(sys.argv)
  File "/Users/phildini/Repos/cards-against-django/lib/python2.7/site-packages/django/core/management/__init__.py", line 338, in execute_from_command_line
    utility.execute()
  File "/Users/phildini/Repos/cards-against-django/lib/python2.7/site-packages/django/core/management/__init__.py", line 312, in execute
    django.setup()
  File "/Users/phildini/Repos/cards-against-django/lib/python2.7/site-packages/django/__init__.py", line 18, in setup
    apps.populate(settings.INSTALLED_APPS)
  File "/Users/phildini/Repos/cards-against-django/lib/python2.7/site-packages/django/apps/registry.py", line 85, in populate
    app_config = AppConfig.create(entry)
  File "/Users/phildini/Repos/cards-against-django/lib/python2.7/site-packages/django/apps/config.py", line 86, in create
    module = import_module(entry)
  File "/System/Library/Frameworks/Python.framework/Versions/2.7/lib/python2.7/importlib/__init__.py", line 37, in import_module
    __import__(name)
  File "/Users/phildini/Repos/cards-against-django/lib/python2.7/site-packages/django_nose/__init__.py", line 4, in <module>
    from django_nose.runner import *
  File "/Users/phildini/Repos/cards-against-django/lib/python2.7/site-packages/django_nose/runner.py", line 20, in <module>
    from django.db.backends.creation import BaseDatabaseCreation
ImportError: No module named creation

==========================================

(cards-against-django)SensitiveDependence:cards-against-django phildini$ CAH_KEY=12345 python manage.py runserver --settings=cah.settings.local
Traceback (most recent call last):
  File "manage.py", line 17, in <module>
    execute_from_command_line(sys.argv)
  File "/Users/phildini/Repos/cards-against-django/lib/python2.7/site-packages/django/core/management/__init__.py", line 338, in execute_from_command_line
    utility.execute()
  File "/Users/phildini/Repos/cards-against-django/lib/python2.7/site-packages/django/core/management/__init__.py", line 312, in execute
    django.setup()
  File "/Users/phildini/Repos/cards-against-django/lib/python2.7/site-packages/django/__init__.py", line 18, in setup
    apps.populate(settings.INSTALLED_APPS)
  File "/Users/phildini/Repos/cards-against-django/lib/python2.7/site-packages/django/apps/registry.py", line 108, in populate
    app_config.import_models(all_models)
  File "/Users/phildini/Repos/cards-against-django/lib/python2.7/site-packages/django/apps/config.py", line 198, in import_models
    self.models_module = import_module(models_module_name)
  File "/System/Library/Frameworks/Python.framework/Versions/2.7/lib/python2.7/importlib/__init__.py", line 37, in import_module
    __import__(name)
  File "/Users/phildini/Repos/cards-against-django/cards/models.py", line 546, in <module>
    @transaction.commit_on_success
AttributeError: 'module' object has no attribute 'commit_on_success'

=================

(cards-against-django)SensitiveDependence:cards-against-django phildini$ CAH_KEY=12345 python manage.py runserver --settings=cah.settings.local
Performing system checks...

System check identified some issues:

WARNINGS:
cards.StandardSubmission.submissions: (fields.W340) null has no effect on ManyToManyField.

System check identified 1 issue (0 silenced).
There is no South database module 'south.db.sqlite3' for your database. Please either choose a supported database, check for SOUTH_DATABASE_ADAPTER[S] settings, or remove South from INSTALLED_APPS.

===================

(cards-against-django)SensitiveDependence:cards-against-django phildini$ CAH_KEY=12345 python manage.py runserver --settings=cah.settings.local
Performing system checks...

System check identified some issues:

WARNINGS:
cards.StandardSubmission.submissions: (fields.W340) null has no effect on ManyToManyField.

System check identified 1 issue (0 silenced).

You have unapplied migrations; your app may not work properly until they are applied.
Run 'python manage.py migrate' to apply them.

May 16, 2015 - 13:49:21
Django version 1.8.1, using settings 'cah.settings.local'
Starting development server at http://127.0.0.1:8000/
Quit the server with CONTROL-C.

================

(cards-against-django)SensitiveDependence:cards-against-django phildini$ CAH_KEY=12345 python manage.py migrate --fake --settings=cah.settings.local
System check identified some issues:

WARNINGS:
cards.StandardSubmission.submissions: (fields.W340) null has no effect on ManyToManyField.
Operations to perform:
  Synchronize unmigrated apps: staticfiles, twitter, messages, allauth, facebook, django_nose, cards, rest_framework
  Apply all migrations: account, sessions, admin, sites, auth, contenttypes, socialaccount
Synchronizing apps without migrations:
  Creating tables...
    Running deferred SQL...
  Installing custom SQL...
Running migrations:
  Rendering model states... DONE
  Applying auth.0001_initial... FAKED
  Applying account.0001_initial... FAKED
  Applying account.0002_auto_20150516_1527... FAKED
  Applying admin.0001_initial... FAKED
  Applying auth.0002_alter_permission_name_max_length... FAKED
  Applying auth.0003_alter_user_email_max_length... FAKED
  Applying auth.0004_alter_user_username_opts... FAKED
  Applying auth.0005_alter_user_last_login_null... FAKED
  Applying auth.0006_require_contenttypes_0002... FAKED
  Applying sessions.0001_initial... FAKED
  Applying sites.0001_initial... FAKED
  Applying socialaccount.0001_initial... FAKED
  Applying socialaccount.0002_auto_20150516_1527... FAKED
(cards-against-django)SensitiveDependence:cards-against-django phildini$


============

ensitiveDependence:cards-against-django phildini$ which python3
/usr/local/bin/python3
SensitiveDependence:cards-against-django phildini$ mkvirtualenv --python=/usr/local/bin/python3 cah_py3
Running virtualenv with interpreter /usr/local/bin/python3
Using base prefix '/usr/local/Cellar/python3/3.4.3/Frameworks/Python.framework/Versions/3.4'
New python executable in cah_py3/bin/python3.4
Also creating executable in cah_py3/bin/python
Installing setuptools, pip...done.
(cah_py3)SensitiveDependence:cards-against-django phildini$

============


(cah_py3)SensitiveDependence:cards-against-django phildini$ pip install -r requirements/local.txt
Downloading/unpacking Django==1.8.2 (from -r requirements/_base.txt (line 2))
  Downloading Django-1.8.2-py2.py3-none-any.whl (6.2MB): 6.2MB downloaded
Downloading/unpacking Unipath==1.1 (from -r requirements/_base.txt (line 3))
  Downloading Unipath-1.1.tar.gz
  Running setup.py (path:/Users/phildini/.virtualenvs/cah_py3/build/Unipath/setup.py) egg_info for package Unipath

Downloading/unpacking django-model-utils==2.2 (from -r requirements/_base.txt (line 4))
  Downloading django-model-utils-2.2.tar.gz
  Running setup.py (path:/Users/phildini/.virtualenvs/cah_py3/build/django-model-utils/setup.py) egg_info for package django-model-utils

Downloading/unpacking wsgiref==0.1.2 (from -r requirements/_base.txt (line 5))
  Downloading wsgiref-0.1.2.zip
  Running setup.py (path:/Users/phildini/.virtualenvs/cah_py3/build/wsgiref/setup.py) egg_info for package wsgiref
    Traceback (most recent call last):
      File "<string>", line 17, in <module>
      File "/Users/phildini/.virtualenvs/cah_py3/build/wsgiref/setup.py", line 5, in <module>
        import ez_setup
      File "/Users/phildini/.virtualenvs/cah_py3/build/wsgiref/ez_setup/__init__.py", line 170
        print "Setuptools version",version,"or greater has been installed."
                                 ^
    SyntaxError: Missing parentheses in call to 'print'
    Complete output from command python setup.py egg_info:
    Traceback (most recent call last):

  File "<string>", line 17, in <module>

  File "/Users/phildini/.virtualenvs/cah_py3/build/wsgiref/setup.py", line 5, in <module>

    import ez_setup

  File "/Users/phildini/.virtualenvs/cah_py3/build/wsgiref/ez_setup/__init__.py", line 170

    print "Setuptools version",version,"or greater has been installed."

                             ^

SyntaxError: Missing parentheses in call to 'print'


----------------------------------------
Cleaning up...
Command python setup.py egg_info failed with error code 1 in /Users/phildini/.virtualenvs/cah_py3/build/wsgiref
Storing debug log for failure in /Users/phildini/.pip/pip.log

==============


Traceback (most recent call last):
  File "/Users/phildini/.virtualenvs/cah_py3/lib/python3.4/site-packages/django/core/handlers/base.py", line 119, in get_response
    resolver_match = resolver.resolve(request.path_info)
  File "/Users/phildini/.virtualenvs/cah_py3/lib/python3.4/site-packages/django/core/urlresolvers.py", line 366, in resolve
    for pattern in self.url_patterns:
  File "/Users/phildini/.virtualenvs/cah_py3/lib/python3.4/site-packages/django/core/urlresolvers.py", line 402, in url_patterns
    patterns = getattr(self.urlconf_module, "urlpatterns", self.urlconf_module)
  File "/Users/phildini/.virtualenvs/cah_py3/lib/python3.4/site-packages/django/core/urlresolvers.py", line 396, in urlconf_module
    self._urlconf_module = import_module(self.urlconf_name)
  File "/Users/phildini/.virtualenvs/cah_py3/lib/python3.4/importlib/__init__.py", line 109, in import_module
    return _bootstrap._gcd_import(name[level:], package, level)
  File "<frozen importlib._bootstrap>", line 2254, in _gcd_import
  File "<frozen importlib._bootstrap>", line 2237, in _find_and_load
  File "<frozen importlib._bootstrap>", line 2226, in _find_and_load_unlocked
  File "<frozen importlib._bootstrap>", line 1200, in _load_unlocked
  File "<frozen importlib._bootstrap>", line 1129, in _exec
  File "<frozen importlib._bootstrap>", line 1471, in exec_module
  File "<frozen importlib._bootstrap>", line 321, in _call_with_frames_removed
  File "/Users/phildini/Repos/cards-against-django/cah/urls.py", line 19, in <module>
    from cards.views.card_views import SubmitCardView, import_cards
  File "/Users/phildini/Repos/cards-against-django/cards/views/card_views.py", line 54
    except ValueError, info:
                     ^
SyntaxError: invalid syntax
[20/May/2015 16:38:36]"GET / HTTP/1.1" 500 88489


